[2024-05-26T11:45:07.219+0000] {local_task_job_runner.py:120} INFO - ::group::Pre task execution logs
[2024-05-26T11:45:07.239+0000] {taskinstance.py:2076} INFO - Dependencies all met for dep_context=non-requeueable deps ti=<TaskInstance: kaggle_to_minio.upload_to_minio manual__2024-05-26T11:45:02.220955+00:00 [queued]>
[2024-05-26T11:45:07.246+0000] {taskinstance.py:2076} INFO - Dependencies all met for dep_context=requeueable deps ti=<TaskInstance: kaggle_to_minio.upload_to_minio manual__2024-05-26T11:45:02.220955+00:00 [queued]>
[2024-05-26T11:45:07.247+0000] {taskinstance.py:2306} INFO - Starting attempt 1 of 2
[2024-05-26T11:45:07.259+0000] {taskinstance.py:2330} INFO - Executing <Task(PythonOperator): upload_to_minio> on 2024-05-26 11:45:02.220955+00:00
[2024-05-26T11:45:07.265+0000] {warnings.py:110} WARNING - /home/***/.local/lib/python3.12/site-packages/***/task/task_runner/standard_task_runner.py:61: DeprecationWarning: This process (pid=157) is multi-threaded, use of fork() may lead to deadlocks in the child.
  pid = os.fork()

[2024-05-26T11:45:07.266+0000] {standard_task_runner.py:63} INFO - Started process 188 to run task
[2024-05-26T11:45:07.266+0000] {standard_task_runner.py:90} INFO - Running: ['***', 'tasks', 'run', 'kaggle_to_minio', 'upload_to_minio', 'manual__2024-05-26T11:45:02.220955+00:00', '--job-id', '56', '--raw', '--subdir', 'DAGS_FOLDER/import_data_dag.py', '--cfg-path', '/tmp/tmpo67ig4ky']
[2024-05-26T11:45:07.267+0000] {standard_task_runner.py:91} INFO - Job 56: Subtask upload_to_minio
[2024-05-26T11:45:07.304+0000] {task_command.py:426} INFO - Running <TaskInstance: kaggle_to_minio.upload_to_minio manual__2024-05-26T11:45:02.220955+00:00 [running]> on host acf1390cef71
[2024-05-26T11:45:07.370+0000] {taskinstance.py:2648} INFO - Exporting env vars: AIRFLOW_CTX_DAG_OWNER='***' AIRFLOW_CTX_DAG_ID='kaggle_to_minio' AIRFLOW_CTX_TASK_ID='upload_to_minio' AIRFLOW_CTX_EXECUTION_DATE='2024-05-26T11:45:02.220955+00:00' AIRFLOW_CTX_TRY_NUMBER='1' AIRFLOW_CTX_DAG_RUN_ID='manual__2024-05-26T11:45:02.220955+00:00'
[2024-05-26T11:45:07.371+0000] {taskinstance.py:430} INFO - ::endgroup::
[2024-05-26T11:45:07.384+0000] {log.py:232} WARNING - 2024-05-26 11:45:07,384 WARNING Retrying (Retry(total=4, connect=None, read=None, redirect=None, status=None)) after connection broken by 'NewConnectionError('<urllib3.connection.HTTPConnection object at 0x7f99bab3be30>: Failed to establish a new connection: [Errno 111] Connection refused')': /kaggle-data?location=
[2024-05-26T11:45:07.384+0000] {connectionpool.py:874} WARNING - Retrying (Retry(total=4, connect=None, read=None, redirect=None, status=None)) after connection broken by 'NewConnectionError('<urllib3.connection.HTTPConnection object at 0x7f99bab3be30>: Failed to establish a new connection: [Errno 111] Connection refused')': /kaggle-data?location=
[2024-05-26T11:45:07.787+0000] {log.py:232} WARNING - 2024-05-26 11:45:07,786 WARNING Retrying (Retry(total=3, connect=None, read=None, redirect=None, status=None)) after connection broken by 'NewConnectionError('<urllib3.connection.HTTPConnection object at 0x7f99bab94aa0>: Failed to establish a new connection: [Errno 111] Connection refused')': /kaggle-data?location=
[2024-05-26T11:45:07.786+0000] {connectionpool.py:874} WARNING - Retrying (Retry(total=3, connect=None, read=None, redirect=None, status=None)) after connection broken by 'NewConnectionError('<urllib3.connection.HTTPConnection object at 0x7f99bab94aa0>: Failed to establish a new connection: [Errno 111] Connection refused')': /kaggle-data?location=
[2024-05-26T11:45:08.589+0000] {log.py:232} WARNING - 2024-05-26 11:45:08,589 WARNING Retrying (Retry(total=2, connect=None, read=None, redirect=None, status=None)) after connection broken by 'NewConnectionError('<urllib3.connection.HTTPConnection object at 0x7f99bab94cb0>: Failed to establish a new connection: [Errno 111] Connection refused')': /kaggle-data?location=
[2024-05-26T11:45:08.589+0000] {connectionpool.py:874} WARNING - Retrying (Retry(total=2, connect=None, read=None, redirect=None, status=None)) after connection broken by 'NewConnectionError('<urllib3.connection.HTTPConnection object at 0x7f99bab94cb0>: Failed to establish a new connection: [Errno 111] Connection refused')': /kaggle-data?location=
[2024-05-26T11:45:10.191+0000] {log.py:232} WARNING - 2024-05-26 11:45:10,191 WARNING Retrying (Retry(total=1, connect=None, read=None, redirect=None, status=None)) after connection broken by 'NewConnectionError('<urllib3.connection.HTTPConnection object at 0x7f99bab95520>: Failed to establish a new connection: [Errno 111] Connection refused')': /kaggle-data?location=
[2024-05-26T11:45:10.191+0000] {connectionpool.py:874} WARNING - Retrying (Retry(total=1, connect=None, read=None, redirect=None, status=None)) after connection broken by 'NewConnectionError('<urllib3.connection.HTTPConnection object at 0x7f99bab95520>: Failed to establish a new connection: [Errno 111] Connection refused')': /kaggle-data?location=
[2024-05-26T11:45:13.394+0000] {log.py:232} WARNING - 2024-05-26 11:45:13,394 WARNING Retrying (Retry(total=0, connect=None, read=None, redirect=None, status=None)) after connection broken by 'NewConnectionError('<urllib3.connection.HTTPConnection object at 0x7f99bab952b0>: Failed to establish a new connection: [Errno 111] Connection refused')': /kaggle-data?location=
[2024-05-26T11:45:13.394+0000] {connectionpool.py:874} WARNING - Retrying (Retry(total=0, connect=None, read=None, redirect=None, status=None)) after connection broken by 'NewConnectionError('<urllib3.connection.HTTPConnection object at 0x7f99bab952b0>: Failed to establish a new connection: [Errno 111] Connection refused')': /kaggle-data?location=
[2024-05-26T11:45:13.396+0000] {taskinstance.py:441} INFO - ::group::Post task execution logs
[2024-05-26T11:45:13.397+0000] {taskinstance.py:2905} ERROR - Task failed with exception
Traceback (most recent call last):
  File "/home/airflow/.local/lib/python3.12/site-packages/urllib3/connection.py", line 198, in _new_conn
    sock = connection.create_connection(
           ^^^^^^^^^^^^^^^^^^^^^^^^^^^^^
  File "/home/airflow/.local/lib/python3.12/site-packages/urllib3/util/connection.py", line 85, in create_connection
    raise err
  File "/home/airflow/.local/lib/python3.12/site-packages/urllib3/util/connection.py", line 73, in create_connection
    sock.connect(sa)
ConnectionRefusedError: [Errno 111] Connection refused

The above exception was the direct cause of the following exception:

Traceback (most recent call last):
  File "/home/airflow/.local/lib/python3.12/site-packages/urllib3/connectionpool.py", line 793, in urlopen
    response = self._make_request(
               ^^^^^^^^^^^^^^^^^^^
  File "/home/airflow/.local/lib/python3.12/site-packages/urllib3/connectionpool.py", line 496, in _make_request
    conn.request(
  File "/home/airflow/.local/lib/python3.12/site-packages/urllib3/connection.py", line 400, in request
    self.endheaders()
  File "/usr/local/lib/python3.12/http/client.py", line 1331, in endheaders
    self._send_output(message_body, encode_chunked=encode_chunked)
  File "/usr/local/lib/python3.12/http/client.py", line 1091, in _send_output
    self.send(msg)
  File "/usr/local/lib/python3.12/http/client.py", line 1035, in send
    self.connect()
  File "/home/airflow/.local/lib/python3.12/site-packages/urllib3/connection.py", line 238, in connect
    self.sock = self._new_conn()
                ^^^^^^^^^^^^^^^^
  File "/home/airflow/.local/lib/python3.12/site-packages/urllib3/connection.py", line 213, in _new_conn
    raise NewConnectionError(
urllib3.exceptions.NewConnectionError: <urllib3.connection.HTTPConnection object at 0x7f99bab95b50>: Failed to establish a new connection: [Errno 111] Connection refused

The above exception was the direct cause of the following exception:

Traceback (most recent call last):
  File "/home/airflow/.local/lib/python3.12/site-packages/airflow/models/taskinstance.py", line 465, in _execute_task
    result = _execute_callable(context=context, **execute_callable_kwargs)
             ^^^^^^^^^^^^^^^^^^^^^^^^^^^^^^^^^^^^^^^^^^^^^^^^^^^^^^^^^^^^^
  File "/home/airflow/.local/lib/python3.12/site-packages/airflow/models/taskinstance.py", line 432, in _execute_callable
    return execute_callable(context=context, **execute_callable_kwargs)
           ^^^^^^^^^^^^^^^^^^^^^^^^^^^^^^^^^^^^^^^^^^^^^^^^^^^^^^^^^^^^
  File "/home/airflow/.local/lib/python3.12/site-packages/airflow/models/baseoperator.py", line 400, in wrapper
    return func(self, *args, **kwargs)
           ^^^^^^^^^^^^^^^^^^^^^^^^^^^
  File "/home/airflow/.local/lib/python3.12/site-packages/airflow/operators/python.py", line 235, in execute
    return_value = self.execute_callable()
                   ^^^^^^^^^^^^^^^^^^^^^^^
  File "/home/airflow/.local/lib/python3.12/site-packages/airflow/operators/python.py", line 252, in execute_callable
    return self.python_callable(*self.op_args, **self.op_kwargs)
           ^^^^^^^^^^^^^^^^^^^^^^^^^^^^^^^^^^^^^^^^^^^^^^^^^^^^^
  File "/opt/airflow/dags/import_data_dag.py", line 36, in upload_to_minio
    if not client.bucket_exists(bucket_name):
           ^^^^^^^^^^^^^^^^^^^^^^^^^^^^^^^^^
  File "/home/airflow/.local/lib/python3.12/site-packages/minio/api.py", line 696, in bucket_exists
    self._execute("HEAD", bucket_name)
  File "/home/airflow/.local/lib/python3.12/site-packages/minio/api.py", line 437, in _execute
    region = self._get_region(bucket_name)
             ^^^^^^^^^^^^^^^^^^^^^^^^^^^^^
  File "/home/airflow/.local/lib/python3.12/site-packages/minio/api.py", line 494, in _get_region
    response = self._url_open(
               ^^^^^^^^^^^^^^^
  File "/home/airflow/.local/lib/python3.12/site-packages/minio/api.py", line 302, in _url_open
    response = self._http.urlopen(
               ^^^^^^^^^^^^^^^^^^^
  File "/home/airflow/.local/lib/python3.12/site-packages/urllib3/poolmanager.py", line 444, in urlopen
    response = conn.urlopen(method, u.request_uri, **kw)
               ^^^^^^^^^^^^^^^^^^^^^^^^^^^^^^^^^^^^^^^^^
  File "/home/airflow/.local/lib/python3.12/site-packages/urllib3/connectionpool.py", line 877, in urlopen
    return self.urlopen(
           ^^^^^^^^^^^^^
  File "/home/airflow/.local/lib/python3.12/site-packages/urllib3/connectionpool.py", line 877, in urlopen
    return self.urlopen(
           ^^^^^^^^^^^^^
  File "/home/airflow/.local/lib/python3.12/site-packages/urllib3/connectionpool.py", line 877, in urlopen
    return self.urlopen(
           ^^^^^^^^^^^^^
  [Previous line repeated 2 more times]
  File "/home/airflow/.local/lib/python3.12/site-packages/urllib3/connectionpool.py", line 847, in urlopen
    retries = retries.increment(
              ^^^^^^^^^^^^^^^^^^
  File "/home/airflow/.local/lib/python3.12/site-packages/urllib3/util/retry.py", line 515, in increment
    raise MaxRetryError(_pool, url, reason) from reason  # type: ignore[arg-type]
    ^^^^^^^^^^^^^^^^^^^^^^^^^^^^^^^^^^^^^^^^^^^^^^^^^^^
urllib3.exceptions.MaxRetryError: HTTPConnectionPool(host='localhost', port=9000): Max retries exceeded with url: /kaggle-data?location= (Caused by NewConnectionError('<urllib3.connection.HTTPConnection object at 0x7f99bab95b50>: Failed to establish a new connection: [Errno 111] Connection refused'))
[2024-05-26T11:45:13.415+0000] {taskinstance.py:1206} INFO - Marking task as UP_FOR_RETRY. dag_id=kaggle_to_minio, task_id=upload_to_minio, run_id=manual__2024-05-26T11:45:02.220955+00:00, execution_date=20240526T114502, start_date=20240526T114507, end_date=20240526T114513
[2024-05-26T11:45:13.426+0000] {standard_task_runner.py:110} ERROR - Failed to execute job 56 for task upload_to_minio (HTTPConnectionPool(host='localhost', port=9000): Max retries exceeded with url: /kaggle-data?location= (Caused by NewConnectionError('<urllib3.connection.HTTPConnection object at 0x7f99bab95b50>: Failed to establish a new connection: [Errno 111] Connection refused')); 188)
[2024-05-26T11:45:13.469+0000] {local_task_job_runner.py:240} INFO - Task exited with return code 1
[2024-05-26T11:45:13.483+0000] {taskinstance.py:3498} INFO - 0 downstream tasks scheduled from follow-on schedule check
[2024-05-26T11:45:13.486+0000] {local_task_job_runner.py:222} INFO - ::endgroup::
