[2024-05-26T11:50:14.735+0000] {local_task_job_runner.py:120} INFO - ::group::Pre task execution logs
[2024-05-26T11:50:14.755+0000] {taskinstance.py:2076} INFO - Dependencies all met for dep_context=non-requeueable deps ti=<TaskInstance: kaggle_to_minio.upload_to_minio manual__2024-05-26T11:45:02.220955+00:00 [queued]>
[2024-05-26T11:50:14.762+0000] {taskinstance.py:2076} INFO - Dependencies all met for dep_context=requeueable deps ti=<TaskInstance: kaggle_to_minio.upload_to_minio manual__2024-05-26T11:45:02.220955+00:00 [queued]>
[2024-05-26T11:50:14.762+0000] {taskinstance.py:2306} INFO - Starting attempt 2 of 2
[2024-05-26T11:50:14.774+0000] {taskinstance.py:2330} INFO - Executing <Task(PythonOperator): upload_to_minio> on 2024-05-26 11:45:02.220955+00:00
[2024-05-26T11:50:14.780+0000] {warnings.py:110} WARNING - /home/***/.local/lib/python3.12/site-packages/***/task/task_runner/standard_task_runner.py:61: DeprecationWarning: This process (pid=252) is multi-threaded, use of fork() may lead to deadlocks in the child.
  pid = os.fork()

[2024-05-26T11:50:14.782+0000] {standard_task_runner.py:63} INFO - Started process 283 to run task
[2024-05-26T11:50:14.782+0000] {standard_task_runner.py:90} INFO - Running: ['***', 'tasks', 'run', 'kaggle_to_minio', 'upload_to_minio', 'manual__2024-05-26T11:45:02.220955+00:00', '--job-id', '57', '--raw', '--subdir', 'DAGS_FOLDER/import_data_dag.py', '--cfg-path', '/tmp/tmpbk2sm5bm']
[2024-05-26T11:50:14.783+0000] {standard_task_runner.py:91} INFO - Job 57: Subtask upload_to_minio
[2024-05-26T11:50:14.822+0000] {task_command.py:426} INFO - Running <TaskInstance: kaggle_to_minio.upload_to_minio manual__2024-05-26T11:45:02.220955+00:00 [running]> on host acf1390cef71
[2024-05-26T11:50:14.886+0000] {taskinstance.py:2648} INFO - Exporting env vars: AIRFLOW_CTX_DAG_OWNER='***' AIRFLOW_CTX_DAG_ID='kaggle_to_minio' AIRFLOW_CTX_TASK_ID='upload_to_minio' AIRFLOW_CTX_EXECUTION_DATE='2024-05-26T11:45:02.220955+00:00' AIRFLOW_CTX_TRY_NUMBER='2' AIRFLOW_CTX_DAG_RUN_ID='manual__2024-05-26T11:45:02.220955+00:00'
[2024-05-26T11:50:14.887+0000] {taskinstance.py:430} INFO - ::endgroup::
[2024-05-26T11:50:18.815+0000] {log.py:232} WARNING - 2024-05-26 11:50:18,815 WARNING Retrying (Retry(total=4, connect=None, read=None, redirect=None, status=None)) after connection broken by 'NameResolutionError("<urllib3.connection.HTTPConnection object at 0x7f99bab94590>: Failed to resolve 'pedantic_grothendieck' ([Errno -2] Name or service not known)")': /kaggle-data?location=
[2024-05-26T11:50:18.815+0000] {connectionpool.py:874} WARNING - Retrying (Retry(total=4, connect=None, read=None, redirect=None, status=None)) after connection broken by 'NameResolutionError("<urllib3.connection.HTTPConnection object at 0x7f99bab94590>: Failed to resolve 'pedantic_grothendieck' ([Errno -2] Name or service not known)")': /kaggle-data?location=
[2024-05-26T11:50:23.090+0000] {log.py:232} WARNING - 2024-05-26 11:50:23,089 WARNING Retrying (Retry(total=3, connect=None, read=None, redirect=None, status=None)) after connection broken by 'NameResolutionError("<urllib3.connection.HTTPConnection object at 0x7f99bb13f560>: Failed to resolve 'pedantic_grothendieck' ([Errno -2] Name or service not known)")': /kaggle-data?location=
[2024-05-26T11:50:23.089+0000] {connectionpool.py:874} WARNING - Retrying (Retry(total=3, connect=None, read=None, redirect=None, status=None)) after connection broken by 'NameResolutionError("<urllib3.connection.HTTPConnection object at 0x7f99bb13f560>: Failed to resolve 'pedantic_grothendieck' ([Errno -2] Name or service not known)")': /kaggle-data?location=
[2024-05-26T11:50:27.836+0000] {log.py:232} WARNING - 2024-05-26 11:50:27,818 WARNING Retrying (Retry(total=2, connect=None, read=None, redirect=None, status=None)) after connection broken by 'NameResolutionError("<urllib3.connection.HTTPConnection object at 0x7f99bab950a0>: Failed to resolve 'pedantic_grothendieck' ([Errno -2] Name or service not known)")': /kaggle-data?location=
[2024-05-26T11:50:27.818+0000] {connectionpool.py:874} WARNING - Retrying (Retry(total=2, connect=None, read=None, redirect=None, status=None)) after connection broken by 'NameResolutionError("<urllib3.connection.HTTPConnection object at 0x7f99bab950a0>: Failed to resolve 'pedantic_grothendieck' ([Errno -2] Name or service not known)")': /kaggle-data?location=
[2024-05-26T11:50:33.318+0000] {log.py:232} WARNING - 2024-05-26 11:50:33,318 WARNING Retrying (Retry(total=1, connect=None, read=None, redirect=None, status=None)) after connection broken by 'NameResolutionError("<urllib3.connection.HTTPConnection object at 0x7f99bab955e0>: Failed to resolve 'pedantic_grothendieck' ([Errno -2] Name or service not known)")': /kaggle-data?location=
[2024-05-26T11:50:33.318+0000] {connectionpool.py:874} WARNING - Retrying (Retry(total=1, connect=None, read=None, redirect=None, status=None)) after connection broken by 'NameResolutionError("<urllib3.connection.HTTPConnection object at 0x7f99bab955e0>: Failed to resolve 'pedantic_grothendieck' ([Errno -2] Name or service not known)")': /kaggle-data?location=
[2024-05-26T11:50:40.442+0000] {log.py:232} WARNING - 2024-05-26 11:50:40,442 WARNING Retrying (Retry(total=0, connect=None, read=None, redirect=None, status=None)) after connection broken by 'NameResolutionError("<urllib3.connection.HTTPConnection object at 0x7f99bab95b80>: Failed to resolve 'pedantic_grothendieck' ([Errno -2] Name or service not known)")': /kaggle-data?location=
[2024-05-26T11:50:40.442+0000] {connectionpool.py:874} WARNING - Retrying (Retry(total=0, connect=None, read=None, redirect=None, status=None)) after connection broken by 'NameResolutionError("<urllib3.connection.HTTPConnection object at 0x7f99bab95b80>: Failed to resolve 'pedantic_grothendieck' ([Errno -2] Name or service not known)")': /kaggle-data?location=
