[2024-05-26T12:42:00.873+0000] {local_task_job_runner.py:120} INFO - ::group::Pre task execution logs
[2024-05-26T12:42:00.894+0000] {taskinstance.py:2076} INFO - Dependencies all met for dep_context=non-requeueable deps ti=<TaskInstance: kaggle_to_minio.upload_to_minio manual__2024-05-26T12:28:52.433715+00:00 [queued]>
[2024-05-26T12:42:00.902+0000] {taskinstance.py:2076} INFO - Dependencies all met for dep_context=requeueable deps ti=<TaskInstance: kaggle_to_minio.upload_to_minio manual__2024-05-26T12:28:52.433715+00:00 [queued]>
[2024-05-26T12:42:00.903+0000] {taskinstance.py:2306} INFO - Starting attempt 2 of 2
[2024-05-26T12:42:00.917+0000] {taskinstance.py:2330} INFO - Executing <Task(PythonOperator): upload_to_minio> on 2024-05-26 12:28:52.433715+00:00
[2024-05-26T12:42:00.923+0000] {warnings.py:110} WARNING - /home/***/.local/lib/python3.12/site-packages/***/task/task_runner/standard_task_runner.py:61: DeprecationWarning: This process (pid=52) is multi-threaded, use of fork() may lead to deadlocks in the child.
  pid = os.fork()

[2024-05-26T12:42:00.925+0000] {standard_task_runner.py:63} INFO - Started process 83 to run task
[2024-05-26T12:42:00.925+0000] {standard_task_runner.py:90} INFO - Running: ['***', 'tasks', 'run', 'kaggle_to_minio', 'upload_to_minio', 'manual__2024-05-26T12:28:52.433715+00:00', '--job-id', '128', '--raw', '--subdir', 'DAGS_FOLDER/import_data_dag.py', '--cfg-path', '/tmp/tmpkdhpyuwc']
[2024-05-26T12:42:00.926+0000] {standard_task_runner.py:91} INFO - Job 128: Subtask upload_to_minio
[2024-05-26T12:42:00.969+0000] {task_command.py:426} INFO - Running <TaskInstance: kaggle_to_minio.upload_to_minio manual__2024-05-26T12:28:52.433715+00:00 [running]> on host f000e974906c
[2024-05-26T12:42:01.054+0000] {taskinstance.py:2648} INFO - Exporting env vars: AIRFLOW_CTX_DAG_OWNER='***' AIRFLOW_CTX_DAG_ID='kaggle_to_minio' AIRFLOW_CTX_TASK_ID='upload_to_minio' AIRFLOW_CTX_EXECUTION_DATE='2024-05-26T12:28:52.433715+00:00' AIRFLOW_CTX_TRY_NUMBER='2' AIRFLOW_CTX_DAG_RUN_ID='manual__2024-05-26T12:28:52.433715+00:00'
[2024-05-26T12:42:01.055+0000] {taskinstance.py:430} INFO - ::endgroup::
[2024-05-26T12:42:05.017+0000] {log.py:232} WARNING - 2024-05-26 12:42:05,017 WARNING Retrying (Retry(total=4, connect=None, read=None, redirect=None, status=None)) after connection broken by 'NameResolutionError("<urllib3.connection.HTTPConnection object at 0x7f26246b3620>: Failed to resolve 'pedantic_grothendieck' ([Errno -2] Name or service not known)")': /kaggle-data?location=
[2024-05-26T12:42:05.017+0000] {connectionpool.py:874} WARNING - Retrying (Retry(total=4, connect=None, read=None, redirect=None, status=None)) after connection broken by 'NameResolutionError("<urllib3.connection.HTTPConnection object at 0x7f26246b3620>: Failed to resolve 'pedantic_grothendieck' ([Errno -2] Name or service not known)")': /kaggle-data?location=
[2024-05-26T12:42:09.294+0000] {log.py:232} WARNING - 2024-05-26 12:42:09,293 WARNING Retrying (Retry(total=3, connect=None, read=None, redirect=None, status=None)) after connection broken by 'NameResolutionError("<urllib3.connection.HTTPConnection object at 0x7f26244b0350>: Failed to resolve 'pedantic_grothendieck' ([Errno -2] Name or service not known)")': /kaggle-data?location=
[2024-05-26T12:42:09.293+0000] {connectionpool.py:874} WARNING - Retrying (Retry(total=3, connect=None, read=None, redirect=None, status=None)) after connection broken by 'NameResolutionError("<urllib3.connection.HTTPConnection object at 0x7f26244b0350>: Failed to resolve 'pedantic_grothendieck' ([Errno -2] Name or service not known)")': /kaggle-data?location=
[2024-05-26T12:42:13.990+0000] {log.py:232} WARNING - 2024-05-26 12:42:13,990 WARNING Retrying (Retry(total=2, connect=None, read=None, redirect=None, status=None)) after connection broken by 'NameResolutionError("<urllib3.connection.HTTPConnection object at 0x7f26244b09e0>: Failed to resolve 'pedantic_grothendieck' ([Errno -2] Name or service not known)")': /kaggle-data?location=
[2024-05-26T12:42:13.990+0000] {connectionpool.py:874} WARNING - Retrying (Retry(total=2, connect=None, read=None, redirect=None, status=None)) after connection broken by 'NameResolutionError("<urllib3.connection.HTTPConnection object at 0x7f26244b09e0>: Failed to resolve 'pedantic_grothendieck' ([Errno -2] Name or service not known)")': /kaggle-data?location=
[2024-05-26T12:42:19.467+0000] {log.py:232} WARNING - 2024-05-26 12:42:19,467 WARNING Retrying (Retry(total=1, connect=None, read=None, redirect=None, status=None)) after connection broken by 'NameResolutionError("<urllib3.connection.HTTPConnection object at 0x7f26244b1400>: Failed to resolve 'pedantic_grothendieck' ([Errno -2] Name or service not known)")': /kaggle-data?location=
[2024-05-26T12:42:19.467+0000] {connectionpool.py:874} WARNING - Retrying (Retry(total=1, connect=None, read=None, redirect=None, status=None)) after connection broken by 'NameResolutionError("<urllib3.connection.HTTPConnection object at 0x7f26244b1400>: Failed to resolve 'pedantic_grothendieck' ([Errno -2] Name or service not known)")': /kaggle-data?location=
[2024-05-26T12:42:26.565+0000] {log.py:232} WARNING - 2024-05-26 12:42:26,564 WARNING Retrying (Retry(total=0, connect=None, read=None, redirect=None, status=None)) after connection broken by 'NameResolutionError("<urllib3.connection.HTTPConnection object at 0x7f26244b1910>: Failed to resolve 'pedantic_grothendieck' ([Errno -2] Name or service not known)")': /kaggle-data?location=
[2024-05-26T12:42:26.564+0000] {connectionpool.py:874} WARNING - Retrying (Retry(total=0, connect=None, read=None, redirect=None, status=None)) after connection broken by 'NameResolutionError("<urllib3.connection.HTTPConnection object at 0x7f26244b1910>: Failed to resolve 'pedantic_grothendieck' ([Errno -2] Name or service not known)")': /kaggle-data?location=
[2024-05-26T12:42:30.483+0000] {taskinstance.py:441} INFO - ::group::Post task execution logs
[2024-05-26T12:42:30.485+0000] {taskinstance.py:2905} ERROR - Task failed with exception
Traceback (most recent call last):
  File "/home/airflow/.local/lib/python3.12/site-packages/urllib3/connection.py", line 198, in _new_conn
    sock = connection.create_connection(
           ^^^^^^^^^^^^^^^^^^^^^^^^^^^^^
  File "/home/airflow/.local/lib/python3.12/site-packages/urllib3/util/connection.py", line 60, in create_connection
    for res in socket.getaddrinfo(host, port, family, socket.SOCK_STREAM):
               ^^^^^^^^^^^^^^^^^^^^^^^^^^^^^^^^^^^^^^^^^^^^^^^^^^^^^^^^^^
  File "/usr/local/lib/python3.12/socket.py", line 963, in getaddrinfo
    for res in _socket.getaddrinfo(host, port, family, type, proto, flags):
               ^^^^^^^^^^^^^^^^^^^^^^^^^^^^^^^^^^^^^^^^^^^^^^^^^^^^^^^^^^^
socket.gaierror: [Errno -2] Name or service not known

The above exception was the direct cause of the following exception:

Traceback (most recent call last):
  File "/home/airflow/.local/lib/python3.12/site-packages/urllib3/connectionpool.py", line 793, in urlopen
    response = self._make_request(
               ^^^^^^^^^^^^^^^^^^^
  File "/home/airflow/.local/lib/python3.12/site-packages/urllib3/connectionpool.py", line 496, in _make_request
    conn.request(
  File "/home/airflow/.local/lib/python3.12/site-packages/urllib3/connection.py", line 400, in request
    self.endheaders()
  File "/usr/local/lib/python3.12/http/client.py", line 1331, in endheaders
    self._send_output(message_body, encode_chunked=encode_chunked)
  File "/usr/local/lib/python3.12/http/client.py", line 1091, in _send_output
    self.send(msg)
  File "/usr/local/lib/python3.12/http/client.py", line 1035, in send
    self.connect()
  File "/home/airflow/.local/lib/python3.12/site-packages/urllib3/connection.py", line 238, in connect
    self.sock = self._new_conn()
                ^^^^^^^^^^^^^^^^
  File "/home/airflow/.local/lib/python3.12/site-packages/urllib3/connection.py", line 205, in _new_conn
    raise NameResolutionError(self.host, self, e) from e
urllib3.exceptions.NameResolutionError: <urllib3.connection.HTTPConnection object at 0x7f26244b2360>: Failed to resolve 'pedantic_grothendieck' ([Errno -2] Name or service not known)

The above exception was the direct cause of the following exception:

Traceback (most recent call last):
  File "/home/airflow/.local/lib/python3.12/site-packages/airflow/models/taskinstance.py", line 465, in _execute_task
    result = _execute_callable(context=context, **execute_callable_kwargs)
             ^^^^^^^^^^^^^^^^^^^^^^^^^^^^^^^^^^^^^^^^^^^^^^^^^^^^^^^^^^^^^
  File "/home/airflow/.local/lib/python3.12/site-packages/airflow/models/taskinstance.py", line 432, in _execute_callable
    return execute_callable(context=context, **execute_callable_kwargs)
           ^^^^^^^^^^^^^^^^^^^^^^^^^^^^^^^^^^^^^^^^^^^^^^^^^^^^^^^^^^^^
  File "/home/airflow/.local/lib/python3.12/site-packages/airflow/models/baseoperator.py", line 400, in wrapper
    return func(self, *args, **kwargs)
           ^^^^^^^^^^^^^^^^^^^^^^^^^^^
  File "/home/airflow/.local/lib/python3.12/site-packages/airflow/operators/python.py", line 235, in execute
    return_value = self.execute_callable()
                   ^^^^^^^^^^^^^^^^^^^^^^^
  File "/home/airflow/.local/lib/python3.12/site-packages/airflow/operators/python.py", line 252, in execute_callable
    return self.python_callable(*self.op_args, **self.op_kwargs)
           ^^^^^^^^^^^^^^^^^^^^^^^^^^^^^^^^^^^^^^^^^^^^^^^^^^^^^
  File "/opt/airflow/dags/import_data_dag.py", line 36, in upload_to_minio
    if not client.bucket_exists(bucket_name):
           ^^^^^^^^^^^^^^^^^^^^^^^^^^^^^^^^^
  File "/home/airflow/.local/lib/python3.12/site-packages/minio/api.py", line 696, in bucket_exists
    self._execute("HEAD", bucket_name)
  File "/home/airflow/.local/lib/python3.12/site-packages/minio/api.py", line 437, in _execute
    region = self._get_region(bucket_name)
             ^^^^^^^^^^^^^^^^^^^^^^^^^^^^^
  File "/home/airflow/.local/lib/python3.12/site-packages/minio/api.py", line 494, in _get_region
    response = self._url_open(
               ^^^^^^^^^^^^^^^
  File "/home/airflow/.local/lib/python3.12/site-packages/minio/api.py", line 302, in _url_open
    response = self._http.urlopen(
               ^^^^^^^^^^^^^^^^^^^
  File "/home/airflow/.local/lib/python3.12/site-packages/urllib3/poolmanager.py", line 444, in urlopen
    response = conn.urlopen(method, u.request_uri, **kw)
               ^^^^^^^^^^^^^^^^^^^^^^^^^^^^^^^^^^^^^^^^^
  File "/home/airflow/.local/lib/python3.12/site-packages/urllib3/connectionpool.py", line 877, in urlopen
    return self.urlopen(
           ^^^^^^^^^^^^^
  File "/home/airflow/.local/lib/python3.12/site-packages/urllib3/connectionpool.py", line 877, in urlopen
    return self.urlopen(
           ^^^^^^^^^^^^^
  File "/home/airflow/.local/lib/python3.12/site-packages/urllib3/connectionpool.py", line 877, in urlopen
    return self.urlopen(
           ^^^^^^^^^^^^^
  [Previous line repeated 2 more times]
  File "/home/airflow/.local/lib/python3.12/site-packages/urllib3/connectionpool.py", line 847, in urlopen
    retries = retries.increment(
              ^^^^^^^^^^^^^^^^^^
  File "/home/airflow/.local/lib/python3.12/site-packages/urllib3/util/retry.py", line 515, in increment
    raise MaxRetryError(_pool, url, reason) from reason  # type: ignore[arg-type]
    ^^^^^^^^^^^^^^^^^^^^^^^^^^^^^^^^^^^^^^^^^^^^^^^^^^^
urllib3.exceptions.MaxRetryError: HTTPConnectionPool(host='pedantic_grothendieck', port=9000): Max retries exceeded with url: /kaggle-data?location= (Caused by NameResolutionError("<urllib3.connection.HTTPConnection object at 0x7f26244b2360>: Failed to resolve 'pedantic_grothendieck' ([Errno -2] Name or service not known)"))
[2024-05-26T12:42:30.503+0000] {taskinstance.py:1206} INFO - Marking task as FAILED. dag_id=kaggle_to_minio, task_id=upload_to_minio, run_id=manual__2024-05-26T12:28:52.433715+00:00, execution_date=20240526T122852, start_date=20240526T124200, end_date=20240526T124230
[2024-05-26T12:42:30.515+0000] {standard_task_runner.py:110} ERROR - Failed to execute job 128 for task upload_to_minio (HTTPConnectionPool(host='pedantic_grothendieck', port=9000): Max retries exceeded with url: /kaggle-data?location= (Caused by NameResolutionError("<urllib3.connection.HTTPConnection object at 0x7f26244b2360>: Failed to resolve 'pedantic_grothendieck' ([Errno -2] Name or service not known)")); 83)
[2024-05-26T12:42:30.534+0000] {local_task_job_runner.py:240} INFO - Task exited with return code 1
[2024-05-26T12:42:30.546+0000] {taskinstance.py:3498} INFO - 0 downstream tasks scheduled from follow-on schedule check
[2024-05-26T12:42:30.548+0000] {local_task_job_runner.py:222} INFO - ::endgroup::
